Workbook

Sheet Índice
A1: Índice de conjuntos de dados — aulas de Bioestatística
A3: # | B3: Aba | C3: Conjunto / contexto | D3: n (obs.) | E3: Variáveis | F3: Técnica estatística sugerida
A4: 1 | B4: 1_bezerro_1am | C4: Pesos de bezerros (amostra única) | D4: =COUNTA('1_bezerro_1am'!A:A)-1 | E4: peso | F4: Descritiva / teste t (1 amostra)
A5: 2 | B5: 2_bezero_2am | C5: Peso por raça (Guzerá × Gir) | D5: =COUNTA('2_bezero_2am'!A:A)-1 | E5: raca, peso | F5: Teste t (2 amostras independentes)
A6: 3 | B6: 4_raca_isop | C6: Peso por tipo de ração (A–D) | D6: =COUNTA('4_raca_isop'!A:A)-1 | E6: racao, peso | F6: ANOVA (DIC)
A7: 4 | B7: 5_cult_tilapia | C7: Produtividade por sistema de cultivo | D7: =COUNTA('5_cult_tilapia'!A:A)-1 | E7: cultura, produtividade | F7: ANOVA (DIC)
A8: 5 | B8: 6_crabs | C8: Morfometria de caranguejos por espécie/sexo | D8: =COUNTA('6_crabs'!A:A)-1 | E8: especie, sexo, FL, RW, CL, CW, BD | F8: Multivariada / regressão
A9: 6 | B9: 7_dens_tilap | C9: Taxa por densidade de estocagem | D9: =COUNTA('7_dens_tilap'!A:A)-1 | E9: densidade, taxa | F9: ANOVA (DIC)
A10: 7 | B10: 10_caranguejos | C10: Morfometria por local/sexo/estação | D10: =COUNTA('10_caranguejos'!A:A)-1 | E10: local, sexo, estacao, LC, CC | F10: ANOVA fatorial / regressão
A11: 8 | B11: 11_leite_tuber | C11: Resposta por suplemento e repetição | D11: =COUNTA('11_leite_tuber'!A:A)-1 | E11: rep, tratamento, resposta | F11: ANOVA (DBC)
A12: 9 | B12: 12_caixa_lagosta | C12: Amostragem estratificada de caixas | D12: =COUNTA('12_caixa_lagosta'!A:A)-1 | E12: estrato, n_caixas, Ni, ni | F12: Amostragem estratificada
A13: 10 | B13: 13_amost_dic | C13: Croqui de delineamento (tanques) | D13: =COUNTA('13_amost_dic'!A:A)-1 | E13: tanque, tr_r | F13: Planejamento experimental (DIC)
A14: 11 | B14: 14_cangulo_regs | C14: Relação comprimento × peso | D14: =COUNTA('14_cangulo_regs'!A:A)-1 | E14: comprimento, P1–P3, peso, ln_comprimento, ln_peso | F14: Regressão (linearização/potência)
A15: 12 | B15: 15_demo_tlc | C15: Amostra para demonstração do TLC | D15: =COUNTA('15_demo_tlc'!A:A)-1 | E15: y | F15: Distribuição amostral / TLC
A16: 13 | B16: 16_pulgoes | C16: Resposta por tratamento | D16: =COUNTA('16_pulgoes'!A:A)-1 | E16: tratamento, resposta | F16: ANOVA (DIC)
A17: 14 | B17: 17_qui2_camar | C17: Sexo × espécie de camarão | D17: =COUNTA('17_qui2_camar'!A:A)-1 | E17: sexo, P_brasiliensis, P_schimitti | F17: Qui-quadrado (contingência)
A18: 15 | B18: 19_cvf | C18: Resposta placebo × droga (mesmos pacientes) | D18: =COUNTA('19_cvf'!A:A)-1 | E18: paciente, placebo, droga | F18: Teste t pareado
A19: 16 | B19: 20_ira | C19: Creatinina por grupo (S/C) | D19: =COUNTA('20_ira'!A:A)-1 | E19: ira, creatinina | F19: Teste t (2 amostras)
A20: 17 | B20: 21_banana_larva_chi2 | C20: Larva × variedade de banana | D20: =COUNTA('21_banana_larva_chi2'!A:A)-1 | E20: larva, variedade1–3 | F20: Qui-quadrado (contingência)
A21: 18 | B21: 22_moscas | C21: Densidade por tipo de vegetação | D21: =COUNTA('22_moscas'!A:A)-1 | E21: tipo, densidade | F21: ANOVA (DIC)
A22: 19 | B22: 23_pardais | C22: Comprimento da asa × idade | D22: =COUNTA('23_pardais'!A:A)-1 | E22: idade, ca | F22: Regressão / correlação
A23: 20 | B23: 24_Bagres | C23: Peso por ração (A–D) | D23: =COUNTA('24_Bagres'!A:A)-1 | E23: racao, peso | F23: ANOVA (DIC)
B25: — Conjuntos-fonte do pacote EAPADados (adicionados na consolidacao) —
B26: src_caranguejos | C26: Morfometria caranguejos (fonte do pacote) | D26: 993 | E26: Local, Sexo, Estacao, LC, CC | F26: Regressao / ANOVA fatorial -> biometria_caranguejos
B27: src_cangulo | C27: Comprimento x peso do cangulo (fonte) | D27: 16 | E27: Comprimento (cm), P1-P3, Peso(g), ln(Peso), ln(Comp) | F27: Regressao potencia -> cangulo_crescimento
B28: src_camaroes_sexo | C28: Sexo x especie de camarao (formato longo) | D28: 170 | E28: Sexo, Especie | F28: Qui-quadrado -> camaroes_sexo
B29: src_artemia | C29: Crescimento de Artemia por racao | D29: 14 | E29: Racao, Taxa | F29: Teste t -> artemia
B30: src_isoproteica | C30: Peso de bagres por racao isoproteica | D30: 19 | E30: Racao, Peso | F30: ANOVA -> isoproteica_bagre
B31: brine_carbonatos | C31: Salmouras de unidades carbonaticas (Davis 2002) | D31: 19 | E31: amostra, grupo, HCO3, SO4, Cl, Ca, Mg, Na | F31: Multivariada -> brine_carbonatos
B32: cabritos_fa_coltro | C32: Acidos graxos em carne de cabritos (Coltro 2005) | D32: 32 | E32: amostra, tratamento, energia, n3, n6, sfa, mufa, pufa... | F32: Multivariada -> cabritos_fa_coltro
B33: captura_pescada_amarela_bruta | C33: Capturas de pescada-amarela (BRUTO, com defeitos) | D33: 252 | E33: Embarcacao, ..., CPUE, Nome Aparelho Pesca | F33: Tratamento de dados -> captura_pescada_amarela
B34: camarao_vannamei_biometria | C34: Biometria de Litopenaeus vannamei (Mendeley CC BY 4.0) | D34: 170 | E34: id_camarao, base, origem, comprimento_cm, cefalotorax_cm, peso_g | F34: Regressao comprimento-peso -> camarao_vannamei_biometria
B35: aquicultura_br | C35: Producao da aquicultura por estado/ano (Revista Peixe-BR) | D35: 216 | E35: uf, estado, posicao, producao_t, ano | F35: Mapas (coropleto geobr) -> aquicultura_br
B36: estacoes_ictiofauna | C36: Estacoes de coleta de ictiofauna (costa do Para) - EXEMPLO | D36: 14 | E36: id_estacao, latitude, longitude, ano, campanha, ambiente, especie, cpue, abundancia | F36: Mapas (pontos/bolhas) -> estacoes_ictiofauna
B37: sst_costa_norte | C37: Grade ambiental (TSM, clorofila, profundidade) costa norte - EXEMPLO | D37: 204 | E37: lon, lat, sst, clorofila, profundidade | F37: Mapas (raster/contorno) -> sst_costa_norte
... B39: cpue_tubarao | C39: CPUE de tubarao por ano/mes/embarcacao (1995-2007) - REAL | D39: 424 | E39: Vessel, Year, Month, CPUE, Data | F39: Kruskal-Wallis (CPUE~Year) + serie temporal

Sheet 1_bezerro_1am
A1: peso
A2: 178
A3: 199
A4: 182
A5: 186
A6: 188
A7: 191
A8: 189
A9: 185
A10: 174
A11: 158

Sheet 2_bezero_2am
A1: raca | B1: peso
A2: Guzerá | B2: 30
A3: Guzerá | B3: 26
A4: Guzerá | B4: 25
A5: Guzerá | B5: 23
A6: Guzerá | B6: 25
A7: Guzerá | B7: 29
A8: Guzerá | B8: 34
A9: Guzerá | B9: 30
A10: Guzerá | B10: 30
A11: Guzerá | B11: 31
A12: Gir | B12: 23
A13: Gir | B13: 21
... A21: Gir | B21: 27

Sheet 4_raca_isop
A1: racao | B1: peso
A2: A | B2: 150.6
A3: A | B3: 128.9
A4: A | B4: 137.2
A5: A | B5: 130.5
A6: B | B6: 225.1
A7: B | B7: 210.6
A8: B | B8: 218.5
A9: B | B9: 224.3
A10: C | B10: 173.8
A11: C | B11: 161.3
A12: C | B12: 155.6
A13: C | B13: 166.4
... A17: D | B17: 306.7

Sheet 5_cult_tilapia
A1: cultura | B1: produtividade
A2: CM | B2: 1.4
A3: CM | B3: 1.2
A4: CM | B4: 1.5
A5: CM | B5: 1.6
A6: TM | B6: 2.5
A7: TM | B7: 3
A8: TM | B8: 2.8
A9: TM | B9: 3
A10: CT | B10: 4
A11: CT | B11: 4.5
A12: CT | B12: 3.5
A13: CT | B13: 3
... A17: TB | B17: 6

Sheet 6_crabs
A1: especie | B1: sexo | C1: FL | D1: RW | E1: CL | F1: CW | G1: BD
A2: azul | B2: M | C2: 8.1 | D2: 6.7 | E2: 16.1 | F2: 19 | G2: 7
A3: azul | B3: M | C3: 8.8 | D3: 7.7 | E3: 18.1 | F3: 20.8 | G3: 7.4
A4: azul | B4: M | C4: 9.2 | D4: 7.8 | E4: 19 | F4: 22.4 | G4: 7.7
A5: azul | B5: M | C5: 9.6 | D5: 7.9 | E5: 20.1 | F5: 23.1 | G5: 8.2
A6: azul | B6: M | C6: 10.8 | D6: 9 | E6: 23 | F6: 26.5 | G6: 9.8
A7: azul | B7: M | C7: 11.6 | D7: 9.1 | E7: 24.5 | F7: 28.4 | G7: 10.4
A8: azul | B8: M | C8: 11.8 | D8: 10.5 | E8: 25.2 | F8: 29.3 | G8: 10.3
A9: azul | B9: M | C9: 12.3 | D9: 11 | E9: 26.8 | F9: 31.5 | G9: 11.4
A10: azul | B10: M | C10: 12.6 | D10: 10 | E10: 27.7 | F10: 31.7 | G10: 11.4
A11: azul | B11: M | C11: 12.8 | D11: 10.9 | E11: 27.4 | F11: 31.5 | G11: 11
A12: azul | B12: M | C12: 12.9 | D12: 11 | E12: 26.8 | F12: 30.9 | G12: 11.4
A13: azul | B13: M | C13: 13.1 | D13: 10.6 | E13: 28.2 | F13: 32.3 | G13: 11
... A38: azul | B38: F | C38: 9.1 | D38: 8.1 | E38: 18.5 | F38: 21.6 | G38: 7.7
A39: azul | B39: F | C39: NA | D39: 8.2 | E39: 19.2 | F39: 22.2 | G39: NA
A40: azul | B40: F | C40: 9.8 | D40: 8.9 | E40: 20.4 | F40: 23.9 | G40: 8.8
A41: azul | B41: F | C41: 10.1 | D41: 9.3 | E41: 20.9 | F41: 24.4 | G41: 8.4
A42: azul | B42: F | C42: 10.3 | D42: 9.5 | E42: 21.3 | F42: 24.7 | G42: 8.9
A43: azul | B43: F | C43: 10.4 | D43: 9.7 | E43: 21.7 | F43: 25.4 | G43: 8.3
A44: azul | B44: F | C44: 10.8 | D44: 9.5 | E44: 22.5 | F44: 26.3 | G44: 9.1
A45: azul | B45: F | C45: 11 | D45: 9.8 | E45: 22.5 | F45: 25.7 | G45: 8.2
A46: azul | B46: F | C46: 11.2 | D46: 10 | E46: 22.8 | F46: 26.9 | G46: 9.4
A47: azul | B47: F | C47: 11.5 | D47: 11 | E47: 24.7 | F47: 29.2 | G47: 10.1
A48: azul | B48: F | C48: 11.6 | D48: 11 | E48: 24.6 | F48: 28.5 | G48: 10.4
A49: azul | B49: F | C49: 11.6 | D49: 11.4 | E49: 23.7 | F49: 27.7 | G49: 10
A50: azul | B50: F | C50: 11.7 | D50: 10.6 | E50: 24.9 | F50: 28.5 | G50: 10.4
A51: azul | B51: F | C51: 11.9 | D51: 11.4 | E51: 26 | F51: 30.1 | G51: 10.9
... A148: laranja | B148: F | C148: 20.1 | D148: 17.2 | E148: 39.8 | F148: 44.1 | G148: 18.6
A149: laranja | B149: F | C149: NA | D149: 16 | E149: 39.4 | F149: 44.1 | G149: NA
A150: laranja | B150: F | C150: 20.5 | D150: 17.5 | E150: 40 | F150: 45.5 | G150: 19.2
A151: laranja | B151: F | C151: 20.9 | D151: 16.5 | E151: 39.9 | F151: 44.7 | G151: 17.5
A152: laranja | B152: F | C152: 21.3 | D152: 18.4 | E152: 43.8 | F152: 48.4 | G152: 20
A153: laranja | B153: F | C153: 21.4 | D153: 18 | E153: 41.2 | F153: 46.2 | G153: 18.7
A154: laranja | B154: F | C154: 21.7 | D154: 17.1 | E154: 41.7 | F154: 47.2 | G154: 19.6
A155: laranja | B155: F | C155: 21.9 | D155: 17.2 | E155: 42.6 | F155: 47.4 | G155: 19.5
A156: laranja | B156: F | C156: 22.5 | D156: 17.2 | E156: 43 | F156: 48.7 | G156: 19.8
A157: laranja | B157: F | C157: 23.1 | D157: 20.2 | E157: 46.2 | F157: 52.5 | G157: 21.1

Sheet 7_dens_tilap
A1: densidade | B1: taxa
A2: A | B2: 4.9
A3: A | B3: 4.1
A4: A | B4: 10.7
A5: A | B5: 8.4
A6: A | B6: 5.8
A7: A | B7: 9.1
A8: A | B8: 6.8
A9: B | B9: 2.3
A10: B | B10: 6.8
A11: B | B11: 5.6
A12: B | B12: 7.1
A13: B | B13: 4.7
... A22: C | B22: 4.1

Sheet 10_caranguejos
A1: local | B1: sexo | C1: estacao | D1: LC | E1: CC
A2: Caratateua | B2: Macho | C2: Seca | D2: 60 | E2: 56
A3: Caratateua | B3: Macho | C3: Seca | D3: 63 | E3: 61
A4: Caratateua | B4: Macho | C4: Seca | D4: 69 | E4: 67
A5: Caratateua | B5: Macho | C5: Seca | D5: 65 | E5: 62
A6: Caratateua | B6: Macho | C6: Seca | D6: 64 | E6: 62
A7: Caratateua | B7: Macho | C7: Seca | D7: 70 | E7: 68
A8: Caratateua | B8: Macho | C8: Seca | D8: 60 | E8: 58
A9: Caratateua | B9: Macho | C9: Seca | D9: 59 | E9: 56
A10: Caratateua | B10: Macho | C10: Seca | D10: 63 | E10: 60
A11: Caratateua | B11: Macho | C11: Seca | D11: 64 | E11: 60
A12: Caratateua | B12: Macho | C12: Seca | D12: 68 | E12: 67
A13: Caratateua | B13: Macho | C13: Seca | D13: 65 | E13: 64
... A994: Ajuruteua | B994: Fêmea | C994: Chuvosa | D994: 75 | E994: 56

Sheet 11_leite_tuber
A1: rep | B1: tratamento | C1: resposta
A2: 1 | B2: Araruta | C2: 35.42
A3: 2 | B3: Araruta | C3: 32.47
A4: 3 | B4: Araruta | C4: 34.48
A5: 4 | B5: Araruta | C5: 33.79
A6: 5 | B6: Araruta | C6: 35.04
A7: 6 | B7: Araruta | C7: 35.19
A8: 1 | B8: Batata Doce | C8: 22.15
A9: 2 | B9: Batata Doce | C9: 24.37
A10: 3 | B10: Batata Doce | C10: 26.54
A11: 4 | B11: Batata Doce | C11: 20.37
A12: 5 | B12: Batata Doce | C12: 19.54
A13: 6 | B13: Batata Doce | C13: 24.06
... A25: 6 | B25: Sem Suplem. | C25: 23.54

Sheet 12_caixa_lagosta
A1: estrato | B1: n_caixas | C1: Ni | D1: ni
A2: E3 | B2: 5 | C2: 270 | D2: 27
A3: E4 | B3: 8 | C3: 324 | D3: 32
A4: E5 | B4: 13 | C4: 421 | D4: 42
A5: E6 | B5: 18 | C5: 486 | D5: 49
A6: E7 | B6: 12 | C6: 278 | D6: 28
A7: E8 | B7: 9 | C7: 182 | D7: 18
A8: E9 | B8: 4 | C8: 72 | D8: 7
A9: E10 | B9: 2 | C9: 32 | D9: 3

Sheet 13_amost_dic
A1: tanque | B1: tr_r
A2: Tanq1 | B2: TR1R1
A3: Tanq2 | B3: TR1R2
A4: Tanq3 | B4: TR1R3
A5: Tanq4 | B5: TR1R4
A6: Tanq5 | B6: TR1R5
A7: Tanq6 | B7: TR2R1
A8: Tanq7 | B8: TR2R2
A9: Tanq8 | B9: TR2R3
A10: Tanq9 | B10: TR2R4
A11: Tanq10 | B11: TR2R5
A12: Tanq11 | B12: TR3R1
... A21: Tanq20 | B21: TR4R5

Sheet 14_cangulo_regs
A1: comprimento | B1: P1 | C1: P2 | D1: P3 | E1: peso | F1: ln_comprimento | G1: ln_peso
A2: 12 | B2: 40.5 | C2: 43.7 | D2: 44.8 | E2: =AVERAGE(B2:D2) | F2: =LN(A2) | G2: =LN(E2)
A3: =2+A2 | B3: 65.4 | C3: 70.2 | D3: 68.7 | E3: =AVERAGE(B3:D3) | F3: =LN(A3) | G3: =LN(E3)
A4: =2+A3 | B4: 95.6 | C4: 106.3 | D4: 98.4 | E4: =AVERAGE(B4:D4) | F4: =LN(A4) | G4: =LN(E4)
A5: =2+A4 | B5: 128.5 | C5: 139.8 | D5: 134 | E5: =AVERAGE(B5:D5) | F5: =LN(A5) | G5: =LN(E5)
A6: =2+A5 | B6: 180 | C6: 203.1 | D6: 195.6 | E6: =AVERAGE(B6:D6) | F6: =LN(A6) | G6: =LN(E6)
A7: =2+A6 | B7: 248.6 | C7: 247.5 | D7: 267.1 | E7: =AVERAGE(B7:D7) | F7: =LN(A7) | G7: =LN(E7)
A8: =2+A7 | B8: 303.7 | C8: 318.9 | D8: 325.4 | E8: =AVERAGE(B8:D8) | F8: =LN(A8) | G8: =LN(E8)
A9: =2+A8 | B9: 420.5 | C9: 373.9 | D9: 380.4 | E9: =AVERAGE(B9:D9) | F9: =LN(A9) | G9: =LN(E9)
A10: =2+A9 | B10: 450.8 | C10: 477.2 | D10: 470.6 | E10: =AVERAGE(B10:D10) | F10: =LN(A10) | G10: =LN(E10)
A11: =2+A10 | B11: 558.8 | C11: 599.3 | D11: 548 | E11: =AVERAGE(B11:D11) | F11: =LN(A11) | G11: =LN(E11)
A12: =2+A11 | B12: 707.5 | C12: 725.8 | D12: 747.4 | E12: =AVERAGE(B12:D12) | F12: =LN(A12) | G12: =LN(E12)
A13: =2+A12 | B13: 861.1 | C13: 817.6 | D13: 838.9 | E13: =AVERAGE(B13:D13) | F13: =LN(A13) | G13: =LN(E13)
A14: =2+A13 | B14: 989.5 | C14: 1030.7 | D14: 1025.6 | E14: =AVERAGE(B14:D14) | F14: =LN(A14) | G14: =LN(E14)
... A17: =2+A16 | B17: 1570 | C17: 1612.5 | D17: 1546.7 | E17: =AVERAGE(B17:D17) | F17: =LN(A17) | G17: =LN(E17)

Sheet 15_demo_tlc
A1: y
A2: 2
A3: 3
A4: 6
A5: 7
A6: 4
A7: 9
A8: 5
A9: 12
A10: 34
A11: 6
A12: 7
A13: 8
... A60: 15

Sheet 16_pulgoes
A1: tratamento | B1: resposta
A2: A | B2: 2370
A3: A | B3: 1687
A4: A | B4: 2592
A5: A | B5: 2283
A6: A | B6: 2910
A7: A | B7: 3020
A8: B | B8: 1282
A9: B | B9: 1527
A10: B | B10: 871
A11: B | B11: 1025
A12: B | B12: 825
A13: B | B13: 920
... A31: E | B31: 44

Sheet 17_qui2_camar
A1: sexo | B1: P_brasiliensis | C1: P_schimitti
A2: Macho | B2: 48 | C2: 52
A3: Fêmea | B3: 45 | C3: 25

Sheet 19_cvf
A1: paciente | B1: placebo | C1: droga
A2: 1 | B2: 224 | C2: 213
A3: 2 | B3: 80 | C3: 95
A4: 3 | B4: 75 | C4: 33
A5: 4 | B5: 541 | C5: 440
A6: 5 | B6: 74 | C6: -32
A7: 6 | B7: 85 | C7: -28
A8: 7 | B8: 293 | C8: 445
A9: 8 | B9: -23 | C9: -178
A10: 9 | B10: 525 | C10: 367
A11: 10 | B11: -38 | C11: 140

Sheet 20_ira
A1: ira | B1: creatinina
A2: S | B2: 0.9
A3: S | B3: 0.8
A4: S | B4: 0.6
A5: S | B5: 0.7
A6: S | B6: 0.8
A7: C | B7: 3.3
A8: C | B8: 3
A9: C | B9: 4
A10: C | B10: 1.5
A11: C | B11: 2.4
A12: C | B12: 0.9

Sheet 21_banana_larva_chi2
A1: larva | B1: variedade1 | C1: variedade2 | D1: variedade3
A2: Larva-Não | B2: 102 | C2: 225 | D2: 14
A3: Larva-Sim | B3: 14 | C3: 26 | D3: 6

Sheet 22_moscas
A1: tipo | B1: densidade
A2: Erv | B2: 14
A3: Erv | B3: 12.1
A4: Erv | B4: 9.6
A5: Erv | B5: 8.2
A6: Erv | B6: 10.2
A7: Arb | B7: 8.4
A8: Arb | B8: 5.1
A9: Arb | B9: 5.5
A10: Arb | B10: 6.6
A11: Arb | B11: 6.3
A12: Arv | B12: 6.9
A13: Arv | B13: 7.3
... A16: Arv | B16: 5.4

Sheet 23_pardais
A1: idade | B1: ca
A2: 3 | B2: 1.4
A3: 4 | B3: 1.5
A4: 5 | B4: 2.2
A5: 6 | B5: 2.4
A6: 8 | B6: 3.1
A7: 9 | B7: 3.2
A8: 10 | B8: 3.2
A9: 11 | B9: 3.9
A10: 12 | B10: 4.1
A11: 14 | B11: 4.7
A12: 15 | B12: 4.5
A13: 16 | B13: 5.2
A14: 17 | B14: 5

Sheet 24_Bagres
A1: racao | B1: peso
A2: A | B2: 86
A3: A | B3: 83
A4: A | B4: 91
A5: A | B5: 84
A6: A | B6: 87
A7: B | B7: 88
A8: B | B8: 87
A9: B | B9: 94
A10: B | B10: 86
A11: B | B11: 89
A12: C | B12: 105
A13: C | B13: 104
... A20: D | B20: 97

Sheet src_caranguejos
A1: Local | B1: Sexo | C1: Estacao | D1: LC | E1: CC
A2: Caratateua | B2: Macho | C2: Seca | D2: 60 | E2: 56
A3: Caratateua | B3: Macho | C3: Seca | D3: 63 | E3: 61
A4: Caratateua | B4: Macho | C4: Seca | D4: 69 | E4: 67
A5: Caratateua | B5: Macho | C5: Seca | D5: 65 | E5: 62
A6: Caratateua | B6: Macho | C6: Seca | D6: 64 | E6: 62
A7: Caratateua | B7: Macho | C7: Seca | D7: 70 | E7: 68
A8: Caratateua | B8: Macho | C8: Seca | D8: 60 | E8: 58
A9: Caratateua | B9: Macho | C9: Seca | D9: 59 | E9: 56
A10: Caratateua | B10: Macho | C10: Seca | D10: 63 | E10: 60
A11: Caratateua | B11: Macho | C11: Seca | D11: 64 | E11: 60
A12: Caratateua | B12: Macho | C12: Seca | D12: 68 | E12: 67
A13: Caratateua | B13: Macho | C13: Seca | D13: 65 | E13: 64
... A994: Ajuruteua | B994: Fêmea | C994: Chuvosa | D994: 75 | E994: 56

Sheet src_cangulo
A1: Comprimento (cm) | B1: P1 | C1: P2 | D1: P3 | E1: Peso(g) | F1: ln(Peso) | G1: ln(Comp)
A2: 12 | B2: 40.5 | C2: 43.7 | D2: 44.8 | E2: 43 | F2: 2.4849066 | G2: 3.7612001
A3: 14 | B3: 65.4 | C3: 70.2 | D3: 68.7 | E3: 68.1 | F3: 2.6390573 | G3: 4.2209772
A4: 16 | B4: 95.6 | C4: 106.3 | D4: 98.4 | E4: 100.1 | F4: 2.7725887 | G4: 4.6061697
A5: 18 | B5: 128.5 | C5: 139.8 | D5: 134 | E5: 134.1 | F5: 2.8903718 | G5: 4.8985858
A6: 20 | B6: 180 | C6: 203.1 | D6: 195.6 | E6: 192.9 | F6: 2.9957323 | G6: 5.2621719
A7: 22 | B7: 248.6 | C7: 247.5 | D7: 267.1 | E7: 254.4 | F7: 3.0910425 | G7: 5.5389078
A8: 24 | B8: 303.7 | C8: 318.9 | D8: 325.4 | E8: 316 | F8: 3.1780538 | G8: 5.7557422
A9: 26 | B9: 420.5 | C9: 373.9 | D9: 380.4 | E9: 391.6 | F9: 3.2580965 | G9: 5.9702409
A10: 28 | B10: 450.8 | C10: 477.2 | D10: 470.6 | E10: 466.2 | F10: 3.3322045 | G10: 6.1446147
A11: 30 | B11: 558.8 | C11: 599.3 | D11: 548 | E11: 568.7 | F11: 3.4011974 | G11: 6.3433531
A12: 32 | B12: 707.5 | C12: 725.8 | D12: 747.4 | E12: 726.9 | F12: 3.4657359 | G12: 6.5887889
A13: 34 | B13: 861.1 | C13: 817.6 | D13: 838.9 | E13: 839.2 | F13: 3.5263605 | G13: 6.7324491
... A17: 42 | B17: 1570 | C17: 1612.5 | D17: 1546.7 | E17: 1576.4 | F17: 3.7376696 | G17: 7.362899

Sheet src_camaroes_sexo
A1: Sexo | B1: Especie
A2: Macho | B2: P.brasiliensis
A3: Macho | B3: P.brasiliensis
A4: Macho | B4: P.brasiliensis
A5: Macho | B5: P.brasiliensis
A6: Macho | B6: P.brasiliensis
A7: Macho | B7: P.brasiliensis
A8: Macho | B8: P.brasiliensis
A9: Macho | B9: P.brasiliensis
A10: Macho | B10: P.brasiliensis
A11: Macho | B11: P.brasiliensis
A12: Macho | B12: P.brasiliensis
... A171: Fêmea | B171: P.schimitti

Sheet src_artemia
A1: Ração | B1: Taxa
A2: A | B2: 4.2
A3: A | B3: 3.6
A4: A | B4: 4.6
A5: A | B5: 4.3
A6: A | B6: 4.1
A7: A | B7: 3.5
A8: A | B8: 4.3
A9: B | B9: 3.7
A10: B | B10: 4
A11: B | B11: 3.2
A12: B | B12: 3.1
A13: B | B13: 2.9
... A15: B | B15: 3.8

Sheet src_isoproteica
A1: Ração | B1: Peso
A2: A | B2: 86
A3: A | B3: 83
A4: A | B4: 91
A5: A | B5: 84
A6: A | B6: 87
A7: B | B7: 88
A8: B | B8: 87
A9: B | B9: 94
A10: B | B10: 86
A11: B | B11: 89
A12: C | B12: 105
A13: C | B13: 104
... A20: D | B20: 97

Sheet brine_carbonatos
A1: amostra | B1: grupo | C1: HCO3 | D1: SO4 | E1: Cl | F1: Ca | G1: Mg | H1: Na
A2: E01 | B2: Ellenburger_Dolomite | C2: 10.4 | D2: 30 | E2: 967.1 | F2: 95.9 | G2: 53.7 | H2: 857.7
A3: E02 | B3: Ellenburger_Dolomite | C3: 6.2 | D3: 29.6 | E3: 1174.9 | F3: 111.7 | G3: 43.9 | H3: 1054.7
A4: E03 | B4: Ellenburger_Dolomite | C4: 2.1 | D4: 11.4 | E4: 2387.1 | F4: 348.3 | G4: 119.3 | H4: 1932.4
A5: E04 | B5: Ellenburger_Dolomite | C5: 8.5 | D5: 22.5 | E5: 2186.1 | F5: 339.6 | G5: 73.6 | H5: 1803.4
A6: E05 | B6: Ellenburger_Dolomite | C6: 6.7 | D6: 32.8 | E6: 2015.5 | F6: 287.6 | G6: 75.1 | H6: 1691.8
A7: E06 | B7: Ellenburger_Dolomite | C7: 3.8 | D7: 18.9 | E7: 2175.8 | F7: 340.4 | G7: 63.8 | H7: 1793.9
A8: E07 | B8: Ellenburger_Dolomite | C8: 1.5 | D8: 16.5 | E8: 2367 | F8: 412 | G8: 95.8 | H8: 1872.5
A9: G08 | B9: Grayburg_Dolomite | C9: 25.6 | D9: 0 | E9: 134.7 | F9: 12.7 | G9: 7.1 | H9: 134.7
A10: G09 | B10: Grayburg_Dolomite | C10: 12 | D10: 104.6 | E10: 3163.8 | F10: 95.6 | G10: 90.1 | H10: 3093.9
A11: G10 | B11: Grayburg_Dolomite | C11: 9 | D11: 104 | E11: 1342.6 | F11: 104.9 | G11: 160.2 | H11: 1190.1
A12: G11 | B12: Grayburg_Dolomite | C12: 13.7 | D12: 103.3 | E12: 2151.6 | F12: 103.7 | G12: 70 | H12: 2054.6
A13: G12 | B13: Grayburg_Dolomite | C13: 16.6 | D13: 92.3 | E13: 905.1 | F13: 91.5 | G13: 50.9 | H13: 871.4
... A20: V19 | B20: Viola_Limestone | C20: 6.3 | D20: 16.7 | E20: 360.9 | F20: 41.9 | G20: 24 | H20: 318.1

Sheet cabritos_fa_coltro
A1: amostra | B1: tratamento | C1: energia_mj_kg | D1: n3 | E1: n6 | F1: n6_n3 | G1: sfa | H1: mufa | I1: pufa | J1: pufa_sfa
A2: 1 | B2: T1 | C2: 9.6 | D2: 0.2641 | E2: 3.7498 | F2: 14.1964 | G2: 50.8125 | H2: 41.5846 | I2: 7.6029 | J2: 0.1496
A3: 2 | B3: T1 | C3: 9.6 | D3: 0.2686 | E3: 3.7584 | F3: 13.9931 | G3: 50.9835 | H3: 41.5317 | I3: 7.4848 | J3: 0.1468
A4: 3 | B4: T1 | C4: 9.6 | D4: 0.2534 | E4: 3.7288 | F4: 14.7119 | G4: 51.2187 | H4: 41.1364 | I4: 7.6448 | J4: 0.1493
A5: 4 | B5: T1 | C5: 9.6 | D5: 0.2646 | E5: 3.8066 | F5: 14.3885 | G5: 50.1781 | H5: 41.9751 | I5: 7.8568 | J5: 0.1538
A6: 5 | B6: T1 | C6: 9.6 | D6: 0.2674 | E6: 3.7707 | F6: 14.1003 | G6: 51.4442 | H6: 41.1296 | I6: 7.4348 | J6: 0.1445
A7: 6 | B7: T1 | C7: 9.6 | D7: 0.2647 | E7: 3.7492 | F7: 14.1617 | G7: 51.7418 | H7: 40.8164 | I7: 7.4419 | J7: 0.1439
A8: 7 | B8: T1 | C8: 9.6 | D8: 0.2615 | E8: 3.711 | F8: 14.1934 | G8: 49.691 | H8: 42.6104 | I8: 7.6985 | J8: 0.1549
A9: 8 | B9: T1 | C9: 9.6 | D9: 0.2574 | E9: 3.7667 | F9: 14.4064 | G9: 50.8604 | H9: 41.5824 | I9: 7.5574 | J9: 0.1486
A10: 9 | B10: T2 | C10: 10.4 | D10: 0.3082 | E10: 3.6688 | F10: 11.9032 | G10: 50.1596 | H10: 44.7324 | I10: 5.1079 | J10: 0.1018
A11: 10 | B11: T2 | C11: 10.4 | D11: 0.3028 | E11: 3.6869 | F11: 12.1748 | G11: 51.0211 | H11: 43.7937 | I11: 5.1851 | J11: 0.1016
A12: 11 | B12: T2 | C12: 10.4 | D12: 0.2986 | E12: 3.6462 | F12: 12.2127 | G12: 50.1743 | H12: 44.7181 | I12: 5.1076 | J12: 0.1018
A13: 12 | B13: T2 | C13: 10.4 | D13: 0.3088 | E13: 3.6534 | F13: 11.8326 | G13: 50.3315 | H13: 44.5703 | I13: 5.0982 | J13: 0.1013
... A33: 32 | B33: T4 | C33: 12.4 | D33: 0.3536 | E33: 3.209 | F33: 9.0741 | G33: 42.496 | H33: 52.671 | I33: 4.8329 | J33: 0.1137

Sheet captura_pescada_amarela_bruta
A1: Embarcacao | B1: Tamanho (m) | C1: Precipitação | D1: Mês | E1: Ano | F1: Período sazonal | G1: Mês/ano | H1: Data de Saida | I1: Data de Chegada | J1: Dias ao mar | K1: CPUE pescada | L1: CPUE | M1: Pessoal Embarcado | N1: Peso Balanca | O1: Nome Aparelho Pesca | P1: Quantidade Aparelho Pesca
A2: B1 | B2: 16 | C2: 370.8 | D2: Janeiro | E2: 2019 | F2: chuvoso | G2: 43466 | H2: 43470 | I2: 43489 | J2: 19 | K2: =N2/J2 | L2: =N2/(M2*J2) | M2: 8 | N2: 2123 | O2: Rede | P2: 15000
A3: B1 | B3: 16 | C3: 426.6 | D3: Fevereiro | E3: 2019 | F3: chuvoso | G3: 43497 | H3: 43499 | I3: 43520 | J3: 21 | K3: =N3/J3 | L3: =N3/(M3*J3) | M3: 8 | N3: 3255 | O3: Rede | P3: 15000
A4: B1 | B4: 16 | C4: 763.8 | D4: Março | E4: 2019 | F4: chuvoso | G4: 43525 | H4: 43531 | I4: 43554 | J4: 23 | K4: =N4/J4 | L4: =N4/(M4*J4) | M4: 8 | N4: 3299 | O4: Rede | P4: 15000
A5: B1 | B5: 16 | C5: 559.6 | D5: Abril | E5: 2019 | F5: chuvoso | G5: 43556 | H5: 43563 | I5: 43581 | J5: 18 | K5: =N5/J5 | L5: =N5/(M5*J5) | M5: 8 | N5: 4781 | O5: Rede | P5: 15000
A6: B1 | B6: 16 | C6: 443.4 | D6: Maio | E6: 2019 | F6: chuvoso | G6: 43586 | H6: 43594 | I6: 43611 | J6: 17 | K6: =N6/J6 | L6: =N6/(M6*J6) | M6: 8 | N6: 2998 | O6: Rede | P6: 15000
A7: B1 | B7: 16 | C7: 253.6 | D7: Junho | E7: 2019 | F7: chuvoso | G7: 43617 | H7: 43623 | I7: 43645 | J7: 22 | K7: =N7/J7 | L7: =N7/(M7*J7) | M7: 8 | N7: 5127 | O7: Rede | P7: 15000
A8: B1 | B8: 16 | C8: 156.2 | D8: Julho | E8: 2019 | F8: seco | G8: 43647 | H8: 43657 | I8: 43673 | J8: 16 | K8: =N8/J8 | L8: =N8/(M8*J8) | M8: 8 | N8: 3014 | O8: Rede | P8: 15000
A9: B1 | B9: 16 | C9: 151 | D9: Agosto | E9: 2019 | F9: seco | G9: 43678 | H9: 43682 | I9: 43702 | J9: 15 | K9: =N6/J9 | L9: =N9/(M9*J9) | M9: 8 | N9: 8235 | O9: Rede | P9: 15000
A10: B1 | B10: 16 | C10: 232.6 | D10: Setembro | E10: 2019 | F10: seco | G10: 43709 | H10: 43711 | I10: 43728 | J10: 17 | K10: =N10/10 | L10: =N10/(M10*J10) | M10: 8 | N10: 6212 | O10: Rede | P10: 15000
A11: B1 | B11: 16 | C11: 274 | D11: Outubro | E11: 2019 | F11: seco | G11: 43739 | H11: 43742 | I11: 43758 | J11: =(I11-H11)+1 | K11: =N11/11 | L11: =N11/(M11*J11) | M11: 8 | N11: 8320 | O11: Rede | P11: 15000
A12: B1 | B12: 16 | C12: 250.4 | D12: Novembro | E12: 2019 | F12: seco | G12: 43770 | H12: 43784 | I12: 43772 | J12: 17 | K12: =N12/12 | L12: =N12/(M12*J12) | M12: 8 | N12: 5987 | O12: Rede | P12: 15000
A13: B1 | B13: 16 | C13: 385 | D13: Dezembro | E13: 2019 | F13: seco | G13: 43800 | H13: 43815 | I13: 43803 | J13: 18 | K13: =N13/13 | L13: =N13/(M13*J13) | M13: 8 | N13: 6989 | O13: Rede | P13: 15000
A14: B2 | B14: 18 | C14: 370.8 | D14: Janeiro | E14: 2019 | F14: chuvoso | G14: 43466 | H14: 43470 | I14: 43488 | J14: =(I14-H14)+1 | K14: =N14/J14 | L14: =N14/(M14*J14) | M14: 10 | N14: 9423 | O14: Espinhel | P14: 4000
A15: B2 | B15: 18 | C15: 426.6 | D15: Fevereiro | E15: 2019 | F15: chuvoso | G15: 43497 | H15: 43500 | I15: 43522 | J15: =(I15-H15)+1 | K15: =N15/J15 | L15: =N15/(M15*J15) | M15: 10 | N15: 8687 | O15: Espinhel | P15: 4000
A16: B2 | B16: 18 | C16: 763.8 | D16: Março | E16: 2019 | F16: chuvoso | G16: 43525 | H16: 43527 | I16: 43551 | J16: =(I16-H16)+1 | K16: =N16/J16 | L16: =N16/(M16*J16) | M16: 10 | N16: 7012 | O16: Espinhel | P16: 4000
A17: B2 | B17: 18 | C17: 559.6 | D17: Abril | E17: 2019 | F17: chuvoso | G17: 43556 | H17: 43563 | I17: 43583 | J17: =(I17-H17)+1 | K17: =N17/J17 | L17: =N17/(M17*J17) | M17: 10 | N17: 8879 | O17: Espinhel | P17: 4000
A18: B2 | B18: 18 | C18: 443.4 | D18: Maio | E18: 2019 | F18: chuvoso | G18: 43586 | H18: 43592 | I18: 43608 | J18: =(I18-H18)+1 | K18: =N18/J18 | L18: =N18/(M18*J18) | M18: 10 | N18: 10106 | O18: Espinhel | P18: 4000
A19: B2 | B19: 18 | C19: 253.6 | D19: Junho | E19: 2019 | F19: chuvoso | G19: 43617 | H19: 43617 | I19: 43643 | J19: =(I19-H19)+1 | K19: =N19/J19 | L19: =N19/(M19*J19) | M19: 10 | N19: 8572 | O19: Espinhel | P19: 4000
A20: B2 | B20: 18 | C20: 156.2 | D20: Julho | E20: 2019 | F20: seco | G20: 43647 | H20: 43656 | I20: 43671 | J20: =(I20-H20)+1 | K20: =N20/J20 | L20: =N20/(M20*J20) | M20: 10 | N20: 8977 | O20: Espinhel | P20: 4000
A21: B2 | B21: 18 | C21: 151 | D21: Agosto | E21: 2019 | F21: seco | G21: 43678 | H21: 43678 | I21: 43706 | J21: =(I21-H21)+1 | K21: =N21/J21 | L21: =N21/(M21*J21) | M21: 10 | N21: 7015 | O21: Espinhel | P21: 4000
A22: B2 | B22: 18 | C22: 232.6 | D22: Setembro | E22: 2019 | F22: seco | G22: 43709 | H22: 43717 | I22: 43738 | J22: =(I22-H22)+1 | K22: =N22/J22 | L22: =N22/(M22*J22) | M22: 10 | N22: 6212 | O22: Espinhel | P22: 4000
A23: B2 | B23: 18 | C23: 274 | D23: Outubro | E23: 2019 | F23: seco | G23: 43739 | H23: 43745 | I23: 43768 | J23: =(I23-H23)+1 | K23: =N23/J23 | L23: =N23/(M23*J23) | M23: 10 | N23: 9187 | O23: Espinhel | P23: 4000
A24: B2 | B24: 18 | C24: 250.4 | D24: Novembro | E24: 2019 | F24: seco | G24: 43770 | H24: 43773 | I24: 43796 | J24: =(I24-H24)+1 | K24: =N24/J24 | L24: =N24/(M24*J24) | M24: 10 | N24: 8474 | O24: Espinhel | P24: 4000
A25: B2 | B25: 18 | C25: 385 | D25: Dezembro | E25: 2019 | F25: seco | G25: 43800 | H25: 43801 | I25: 43817 | J25: =(I25-H25)+1 | K25: =N25/J25 | L25: =N25/(M25*J25) | M25: 10 | N25: 8687 | O25: Espinhel | P25: 4000
... A57: B5 | B57: 17 | C57: 151 | D57: Agosto | E57: 2019 | F57: seco | G57: 43678 | H57: 43681 | I57: 43706 | J57: =(I57-H57)+1 | K57: =N57/J57 | L57: =N57/(M57*J57) | M57: 10 | N57: 9322 | O57: Espinhel | P57: 3500
A58: B5 | B58: 17 | C58: 232.6 | D58: Setembro | E58: 2019 | F58: seco | G58: 43709 | H58: 43717 | I58: 43731 | J58: =(I58-H58)+1 | K58: =N56/J58 | L58: =N56/(M58*J58) | M58: 10 | N58: 8369 | O58: Espinhel | P58: 3500
A59: B5 | B59: 17 | C59: 274 | D59: Outubro | E59: 2019 | F59: seco | G59: 43739 | H59: 43738 | I59: 43755 | J59: =(I59-H59)+1 | K59: =N59/J59 | L59: =N59/(M59*J59) | M59: 10 | N59: 11921 | O59: Espinhel | P59: 3500
A60: B5 | B60: 17 | C60: 250.4 | D60: Novembro | E60: 2019 | F60: seco | G60: 43770 | H60: 43762 | I60: 43781 | J60: =(I60-H60)+1 | K60: =N60/J60 | L60: =N60/(M60*J60) | M60: 10 | N60: 6993 | O60: Espinhel | P60: 3500
A61: B5 | B61: 17 | C61: 385 | D61: Dezembro | E61: 2019 | F61: seco | G61: 43800 | H61: 43791 | I61: 43817 | J61: =(I61-H61)+1 | K61: =N61/J61 | L61: =N61/(M61*J61) | M61: 10 | N61: 6325 | O61: Espinhel | P61: 3500
A62: B6 | B62: 17 | C62: 370.8 | D62: Janeiro | E62: 2019 | F62: chuvoso | G62: 43466 | H62: 43474 | I62: 43489 | J62: =(I62-H62)+1 | K62: =N62/J62 | L62: =N62/(M62*J62) | M62: 10 | N62: 7712 | O62: Espinhel | P62: 4000
A63: B6 | B63: 17 | C63: 426.6 | D63: Fevereiro | E63: 2019 | F63: chuvoso | G63: 43497 | H63: 43494 | I63: 43511 | J63: =(I63-H63)+1 | K63: =N63/J63 | L63: =N63/(M63*J63) | M63: 10 | N63: 10426 | O63: Espinhel | P63: 4000
A64: B6 | B64: 17 | C64: 763.8 | D64: Março | E64: 2019 | F64: chuvoso | G64: 43525 | H64: 43521 | I64: 43543 | J64: =(I64-H64)+1 | K64: =N64/J64 | L64: =N64/(M64*J64) | M64: 10 | N64: 6701 | O64: Espinhel | P64: 4000
A65: B6 | B65: 17 | C65: 559.6 | D65: Abril | E65: 2019 | F65: chuvoso | G65: 43556 | H65: 43550 | I65: 43575 | J65: =(I65-H65)+1 | K65: =N65/J65 | L65: =N65/(M65*J65) | M65: 10 | N65: 7100 | O65: Espinhel | P65: 4000
A66: B6 | B66: 17 | C66: 443.4 | D66: Maio | E66: 2019 | F66: chuvoso | G66: 43586 | H66: 43586 | I66: 43603 | J66: =(I66-H66)+1 | K66: =N66/J66 | L66: =N66/(M66*J66) | M66: 10 | N66: 3060 | O66: Espinhel | P66: 4000
A67: B6 | B67: 17 | C67: 253.6 | D67: Junho | E67: 2019 | F67: chuvoso | G67: 43617 | H67: 43610 | I67: 43635 | J67: =(I67-H67)+1 | K67: =N67/J67 | L67: =N67/(M67*J67) | M67: 10 | N67: 5120 | O67: Espinhel | P67: 4000
A68: B6 | B68: 17 | C68: 156.2 | D68: Julho | E68: 2019 | F68: seco | G68: 43647 | H68: 43645 | I68: 43666 | J68: =(I68-H68)+1 | K68: =N68/J68 | L68: =N68/(M68*J68) | M68: 10 | N68: 8063 | O68: Espinhel | P68: 4000
A69: B6 | B69: 17 | C69: 151 | D69: Agosto | E69: 2019 | F69: seco | G69: 43678 | H69: 43676 | I69: 43698 | J69: =(I69-H69)+1 | K69: =N69/J69 | L69: =N69/(M69*J69) | M69: 10 | N69: 1140 | O69: Espinhel | P69: 4000
A70: B6 | B70: 17 | C70: 232.6 | D70: Setembro | E70: 2019 | F70: seco | G70: 43709 | H70: 43708 | I70: 43735 | J70: =(I70-H70)+1 | K70: =N70/J70 | L70: =N70/(M70*J70) | M70: 10 | N70: 5500 | O70: Espinhel | P70: 4000
... A118: B3 | B118: 18 | C118: 151.6 | D118: Setembro | E118: 2020 | F118: seco | G118: 44075 | H118: 44073 | I118: 44097 | J118: =(I118-H118)+1 | K118: =N118/J118 | L118: =N118/(M118*J118) | M118: 10 | N118: 5110 | O118: Espinhel | P118: 4500
...

Sheet camarao_vannamei_biometria
A1: id_camarao | B1: base | C1: origem | D1: arquivo_origem | E1: amostra | F1: comprimento_cm | G1: cefalotorax_cm | H1: peso_g | I1: imagem_completa
A2: DB1_001 | B2: DB1 | C2: fazenda_industrial | D2: DB1_INDUSTRIAL_FARM_1.xlsx | E2: 1 | F2: 12.2 | H2: 33 | I2: 1
A3: DB1_002 | B3: DB1 | C3: fazenda_industrial | D3: DB1_INDUSTRIAL_FARM_1.xlsx | E3: 2 | F3: 14.4 | H3: 33 | I3: 1
A4: DB1_003 | B4: DB1 | C4: fazenda_industrial | D4: DB1_INDUSTRIAL_FARM_1.xlsx | E4: 3 | F4: 12.24 | H4: 31 | I4: 1
A5: DB1_004 | B5: DB1 | C5: fazenda_industrial | D5: DB1_INDUSTRIAL_FARM_1.xlsx | E5: 4 | F5: 12.4 | H5: 34 | I5: 0
A6: DB1_005 | B6: DB1 | C6: fazenda_industrial | D6: DB1_INDUSTRIAL_FARM_1.xlsx | E6: 5 | F6: 11 | H6: 19 | I6: 0
A7: DB1_006 | B7: DB1 | C7: fazenda_industrial | D7: DB1_INDUSTRIAL_FARM_1.xlsx | E7: 6 | F7: 12.36 | H7: 32 | I7: 1
A8: DB1_007 | B8: DB1 | C8: fazenda_industrial | D8: DB1_INDUSTRIAL_FARM_1.xlsx | E8: 7 | F8: 10.44 | H8: 23 | I8: 1
A9: DB1_008 | B9: DB1 | C9: fazenda_industrial | D9: DB1_INDUSTRIAL_FARM_1.xlsx | E9: 8 | F9: 11.97 | H9: 32 | I9: 1
A10: DB1_009 | B10: DB1 | C10: fazenda_industrial | D10: DB1_INDUSTRIAL_FARM_1.xlsx | E10: 9 | F10: 13.64 | H10: 40 | I10: 1
A11: DB1_010 | B11: DB1 | C11: fazenda_industrial | D11: DB1_INDUSTRIAL_FARM_1.xlsx | E11: 10 | F11: 12.19 | H11: 32 | I11: 1
A12: DB1_011 | B12: DB1 | C12: fazenda_industrial | D12: DB1_INDUSTRIAL_FARM_1.xlsx | E12: 11 | F12: 12.19 | H12: 30 | I12: 1
A13: DB1_012 | B13: DB1 | C13: fazenda_industrial | D13: DB1_INDUSTRIAL_FARM_1.xlsx | E13: 12 | F13: 13.16 | H13: 41 | I13: 1
... A23: DB1_022 | B23: DB1 | C23: fazenda_industrial | D23: DB1_INDUSTRIAL_FARM_1.xlsx | E23: 22 | F23: 11.32 | H23: 28 | I23: 0
A24: DB2_001 | B24: DB2 | C24: fazenda_industrial | D24: DB2_INDUSTRIAL_FARM_2_C1.xlsx | E24: 1 | F24: 10.5 | G24: 3.32 | H24: 22 | I24: 1
A25: DB2_002 | B25: DB2 | C25: fazenda_industrial | D25: DB2_INDUSTRIAL_FARM_2_C1.xlsx | E25: 2 | F25: 11.5 | G25: 3.5 | H25: 29 | I25: 1
A26: DB2_003 | B26: DB2 | C26: fazenda_industrial | D26: DB2_INDUSTRIAL_FARM_2_C1.xlsx | E26: 3 | F26: 11 | G26: 3.19 | H26: 27 | I26: 1
A27: DB2_004 | B27: DB2 | C27: fazenda_industrial | D27: DB2_INDUSTRIAL_FARM_2_C1.xlsx | E27: 4 | F27: 11.5 | G27: 3.41 | H27: 32 | I27: 1
A28: DB2_005 | B28: DB2 | C28: fazenda_industrial | D28: DB2_INDUSTRIAL_FARM_2_C1.xlsx | E28: 5 | F28: 11.5 | G28: 3.4 | H28: 32 | I28: 1
A29: DB2_006 | B29: DB2 | C29: fazenda_industrial | D29: DB2_INDUSTRIAL_FARM_2_C1.xlsx | E29: 6 | F29: 11.9 | G29: 3.58 | H29: 37 | I29: 1
A30: DB2_007 | B30: DB2 | C30: fazenda_industrial | D30: DB2_INDUSTRIAL_FARM_2_C1.xlsx | E30: 7 | F30: 12.2 | G30: 3.68 | H30: 38 | I30: 1
A31: DB2_008 | B31: DB2 | C31: fazenda_industrial | D31: DB2_INDUSTRIAL_FARM_2_C1.xlsx | E31: 8 | F31: 12.2 | G31: 3.88 | H31: 39 | I31: 1
A32: DB2_009 | B32: DB2 | C32: fazenda_industrial | D32: DB2_INDUSTRIAL_FARM_2_C1.xlsx | E32: 9 | F32: 11 | G32: 3.62 | H32: 30 | I32: 1
A33: DB2_010 | B33: DB2 | C33: fazenda_industrial | D33: DB2_INDUSTRIAL_FARM_2_C1.xlsx | E33: 10 | F33: 11 | G33: 3.44 | H33: 31 | I33: 0
A34: DB2_011 | B34: DB2 | C34: fazenda_industrial | D34: DB2_INDUSTRIAL_FARM_2_C1.xlsx | E34: 11 | F34: 10.5 | G34: 3.34 | H34: 22 | I34: 0
A35: DB2_012 | B35: DB2 | C35: fazenda_industrial | D35: DB2_INDUSTRIAL_FARM_2_C1.xlsx | E35: 12 | F35: 11 | G35: 3.35 | H35: 29 | I35: 1
... A171: DB5_020 | B171: DB5 | C171: viveiro_academico | D171: DB5_ACADEMIC_POND_S2.xlsx | E171: 20 | F171: 7.56 | G171: 2.76 | H171: 7 | I171: 1

Sheet aquicultura_br
A1: uf | B1: estado | C1: posicao | D1: producao_t | E1: ano
A2: PR | B2: PARANÁ | C2: 1 | D2: 213300 | E2: 2023
A3: SP | B3: SÃO PAULO | C3: 2 | D3: 82400 | E3: 2023
A4: MG | B4: MINAS GERAIS | C4: 3 | D4: 61600 | E4: 2023
A5: RO | B5: RONDÔNIA | C5: 4 | D5: 56500 | E5: 2023
A6: SC | B6: SANTA CATARINA | C6: 5 | D6: 56100 | E6: 2023
A7: MA | B7: MARANHÃO | C7: 6 | D7: 49143 | E7: 2023
A8: MT | B8: MATO GROSSO | C8: 7 | D8: 44900 | E8: 2023
A9: MS | B9: MATO GROSSO DO SUL | C9: 8 | D9: 34100 | E9: 2023
A10: BA | B10: BAHIA | C10: 9 | D10: 34000 | E10: 2023
A11: PE | B11: PERNAMBUCO | C11: 10 | D11: 32200 | E11: 2023
A12: GO | B12: GOIÁS | C12: 11 | D12: 29850 | E12: 2023
A13: RS | B13: RIO GRANDE DO SUL | C13: 12 | D13: 26800 | E13: 2023
... A217: AP | B217: AMAPÁ | C217: 27 | D217: 650 | E217: 2016

Sheet estacoes_ictiofauna
A1: id_estacao | B1: latitude | C1: longitude | D1: ano | E1: campanha | F1: ambiente | G1: especie | H1: cpue | I1: abundancia
A2: E01 | B2: -0.829 | C2: -46.604 | D2: 2023 | E2: Seca | F2: Praia | G2: Pescada-amarela | H2: 12.4 | I2: 31
A3: E02 | B3: -0.88 | C3: -46.63 | D3: 2023 | E3: Seca | F3: Manguezal | G3: Bagre | H3: 28.7 | I3: 64
A4: E03 | B4: -0.78 | C4: -46.63 | D4: 2023 | E4: Seca | F4: Estuario | G4: Robalo | H4: 19.1 | I4: 40
A5: E04 | B5: -0.95 | C5: -46.68 | D5: 2023 | E5: Seca | F5: Manguezal | G5: Bagre | H5: 22.3 | I5: 51
A6: E05 | B6: -1.0536 | C6: -46.7656 | D6: 2023 | E6: Seca | F6: Estuario | G6: Pescada-amarela | H6: 15.8 | I6: 37
A7: E06 | B7: -0.616 | C7: -47.356 | D7: 2023 | E7: Seca | F7: Praia | G7: Robalo | H7: 9.6 | I7: 22
A8: E07 | B8: -0.77 | C8: -47.18 | D8: 2023 | E8: Seca | F8: Plataforma | G8: Pescada-amarela | H8: 33.5 | I8: 70
A9: E08 | B9: -0.5 | C9: -47 | D9: 2023 | E9: Seca | F9: Plataforma | G9: Pescada-amarela | H9: 41.2 | I9: 88
A10: E09 | B10: -0.829 | C10: -46.604 | D10: 2024 | E10: Chuvosa | F10: Praia | G10: Pescada-amarela | H10: 18.9 | I10: 44
A11: E10 | B11: -0.88 | C11: -46.63 | D11: 2024 | E11: Chuvosa | F11: Manguezal | G11: Bagre | H11: 35.1 | I11: 79
A12: E11 | B12: -0.78 | C12: -46.63 | D12: 2024 | E12: Chuvosa | F12: Estuario | G12: Robalo | H12: 24.6 | I12: 52
A13: E12 | B13: -1.0536 | C13: -46.7656 | D13: 2024 | E13: Chuvosa | F13: Estuario | G13: Pescada-amarela | H13: 21 | I13: 49
... A15: E14 | B15: -0.5 | C15: -47 | D15: 2024 | E15: Chuvosa | F15: Plataforma | G15: Pescada-amarela | H15: 52.3 | I15: 110

Sheet sst_costa_norte
A1: lon | B1: lat | C1: sst | D1: clorofila | E1: profundidade
A2: -48.5 | B2: -1.5 | C2: 27.41 | D2: 3.36 | E2: 5
A3: -48.35 | B3: -1.5 | C3: 27.59 | D3: 3.32 | E3: 4.2
A4: -48.2 | B4: -1.5 | C4: 27.52 | D4: 3.36 | E4: 5.9
A5: -48.05 | B5: -1.5 | C5: 27.51 | D5: 3.38 | E5: 5.8
A6: -47.9 | B6: -1.5 | C6: 27.56 | D6: 3.36 | E6: 4.2
A7: -47.75 | B7: -1.5 | C7: 27.53 | D7: 3.32 | E7: 6
A8: -47.6 | B8: -1.5 | C8: 27.49 | D8: 3.39 | E8: 5.6
A9: -47.45 | B9: -1.5 | C9: 27.54 | D9: 3.33 | E9: 4.3
A10: -47.3 | B10: -1.5 | C10: 27.62 | D10: 3.4 | E10: 5.9
A11: -47.15 | B11: -1.5 | C11: 27.62 | D11: 3.36 | E11: 3.7
A12: -47 | B12: -1.5 | C12: 27.46 | D12: 3.36 | E12: 4.4
A13: -46.85 | B13: -1.5 | C13: 27.49 | D13: 3.39 | E13: 5.6
... A205: -46.1 | B205: 0.15 | C205: 28.92 | D205: 0.39 | E205: 64.2

Sheet ocorrencias_peixes
A1: id | B1: longitude | C1: latitude | D1: especie | E1: ano
A2: 1 | B2: -46.8324 | C2: -0.9809 | D2: Pescada-amarela | E2: 2024
A3: 2 | B3: -46.6701 | C3: -0.8963 | D3: Pescada-amarela | E3: 2023
A4: 3 | B4: -47.3947 | C4: -0.5863 | D4: Camarao-rosa | E4: 2024
A5: 4 | B5: -47.473 | C5: -0.3827 | D5: Camarao-rosa | E5: 2023
A6: 5 | B6: -47.077 | C6: -0.6631 | D6: Camarao-rosa | E6: 2024
A7: 6 | B7: -47.2852 | C7: -1.0134 | D7: Camarao-rosa | E7: 2024
A8: 7 | B8: -47.0228 | C8: -0.5986 | D8: Camarao-rosa | E8: 2023
A9: 8 | B9: -47.426 | C9: -0.6696 | D9: Camarao-rosa | E9: 2024
A10: 9 | B10: -46.7138 | C10: -0.8237 | D10: Pescada-amarela | E10: 2024
A11: 10 | B11: -47.2183 | C11: -0.5166 | D11: Camarao-rosa | E11: 2024
A12: 11 | B12: -47.3326 | C12: -0.6173 | D12: Camarao-rosa | E12: 2023
A13: 12 | B13: -47.0942 | C13: -0.8323 | D13: Camarao-rosa | E13: 2023
... A126: 125 | B126: -47.1072 | C126: -0.3273 | D126: Camarao-rosa | E126: 2023

Sheet cpue_tubarao
A1: Vessel | B1: Year | C1: Month | D1: CPUE | E1: Data
A2: MB | B2: 1995 | C2: 1 | D2: 12.95 | E2: 34708
A3: MC | B3: 1995 | C3: 1 | D3: 21.283333 | E3: 34715
A4: SB | B4: 1995 | C4: 1 | D4: 25.74 | E4: 34725
A5: SB | B5: 1995 | C5: 2 | D5: 4.04 | E5: 34751
A6: SB | B6: 1995 | C6: 3 | D6: 3.25 | E6: 34773
A7: MB | B7: 1995 | C7: 4 | D7: 12.550667 | E7: 34798
A8: MC | B8: 1995 | C8: 4 | D8: 2.72 | E8: 34800
A9: SB | B9: 1995 | C9: 4 | D9: 15.395 | E9: 34815
A10: MB | B10: 1995 | C10: 6 | D10: 17.381875 | E10: 34864
A11: SB | B11: 1995 | C11: 6 | D11: 17.493077 | E11: 34867
A12: MC | B12: 1995 | C12: 6 | D12: 15.3 | E12: 34870
A13: MC | B13: 1995 | C13: 8 | D13: 62.5325 | E13: 34925
... A425: SB | B425: 2007 | C425: 12 | D425: 3.135 | E425: 39436
